Workbook
Name FLETEYIWU1: '1.CÁL'!$H$14
Name TOTAL1: 'c. LIQ LCL D'!$E$37
Name CAJAS: '1.CÁL'!$K$3:$K$5
Name TOTALUSD: '1.CÁL'!$O$3:$O$5
Name ab.IMPR3: #REF!
Name TOTAL2: #REF!
Name CBMTOTAL: '1.CÁL'!$Q$3:$Q$5
Name CANDADOS: '1.CÁL'!$S$11:$S$13
Name TOTAL2: a.LIQ!$F$65
Name ab.IMPR1: #REF!
Name ISD: '1.CÁL'!$G$11:$G$13
Name TOTALIMP: #REF!
Name SUBTOTALLF: #REF!
Name TOTAL3: #REF!
Name aa.IMPRIMIRLIQUIDACION: 'c. LIQ LCL D'!$B$3:$F$58
Name PVOLUMETRICO: '1.CÁL'!$S$3:$S$5
Name RUBROSL: a.LIQ!$E$16:$F$27
Name SUBTOTALL: 'a.1 LIQ PD'!$F$63:$F$65
Name CAJAS1: '1.CÁL'!$K$6
Name PESO: '1.CÁL'!$R$3:$R$5
Name VALORUSD: '1.CÁL'!$C$11:$C$13
Name ac.IMPRbFACTOR: 'b. LIQ.F'!$B$2:$F$43
Name CBMTOTAL1: '1.CÁL'!$Q$6
Name SUBTOTALLF: #REF!
Name TOTAL2: 'a.1 LIQ PD'!$F$66
Name TOTALUSD1: '1.CÁL'!$O$6
Name FLETEYIWU: '1.CÁL'!$H$11:$H$13
Name MONTACARGA: '1.CÁL'!$J$11:$J$13
Name aa.IMPRIMIRLIQUIDACION: 'a.1 LIQ PD'!$B$3:$F$66
Name IVA: '1.CÁL'!$P$11:$P$13
Name COMISIONBANC: '1.CÁL'!$I$11:$I$13
Name RUBROSL: 'c. LIQ LCL D'!$E$19:$F$33
Name SLOGISTICOS: '1.CÁL'!$Q$11:$Q$13
Name ab.IMPR2: #REF!
Name ICE: '1.CÁL'!$N$11:$N$13
Name TOTAL1: 'a.1 LIQ PD'!$E$30
Name GICHINA: '1.CÁL'!$D$11:$D$13
Name FLETEMAR: '1.CÁL'!$E$11:$E$13
Name TOTAL1: a.LIQ!$E$30
Name TCATEGORIAB: #REF!
Name RUBROSL: 'a.1 LIQ PD'!$E$16:$F$27
Name SUBTOTALL: #REF!
Name TCATEGORIAC: #REF!
Name TRANSPORTEECU: '1.CÁL'!$K$11:$K$13
Name SUBTOTALL: a.LIQ!$F$62:$F$64
Name SEGURO: '1.CÁL'!$F$11:$F$13
Name ARANCEL: '1.CÁL'!$M$11:$M$13
Name aa.IMPRIMIRLIQUIDACION: a.LIQ!$B$3:$F$65

Sheet 1.CÁL
A2: LINK COTIZADOR | B2: PROVEEDORES | C2: PROVEEDORES 2 | D2: MODELO | E2: FOTO | F2: LINK DE LA IMAGEN | G2: DESCRIPCION | H2: NOMBRE COMERCIAL | I2: UNIDAD DE MEDIDA | J2: CANTIDAD x CAJA | K2: CAJAS | L2: TOTAL UNIDADES | M2: PRECIO UNITARIO YUANES | N2: PRECIO UNITARIO USD | O2: TOTAL USD | P2: CBM | Q2: CBM TOTAL | R2: PESO (KG) | S2: W/M | T2: FLETE YIWU | U2: PARTIDA | V2: TNAN | W2: ARANCEL (%) | X2: ARANCEL TLC (%) | Y2: PERMISOS | Z2: INCREMENTO ICE | AA2: ICE ADVALOREM | AB2: PARTIDA 2 | AC2: TNAN 2 | AD2: PERMISOS 2 | AE2: NOMBRE COMERCIAL
B3: =IF(C3="PA",1,IF(C3="PB",2,IF(C3="PC",3,IF(C3="PD",4,IF(C3="PE",5,IF(C3="PF",6,IF(C3="PG",7,IF(C3="PH",8,IF(C3="PI",9,IF(C3="PJ",10,IF(C3="PK",11,IF(C3="PL",12,IF(C3="PM",13,IF(C3="PN",14,IF(C3="PO",15,IF(C3="PP",15,IF(C3="PQ",16,IF(C3="PR",17,0)))))))))))))))))) -> 1 | C3: PA | E3: =IMAGE(F3) -> #REF! | F3: https://drive.google.com/uc?export=view&id=1vcrZn_OLPxflHITc9KAVYfonNcP_7xys | I3: PZA | J3: 1 | K3: 1 | L3: =K3*J3 -> 1 | O3: =IF(AND(M3>0,N3>0),FALSE,IF(M3>0,M3*L3/6.65,N3*L3)) -> 0 | Q3: =P3*K3 -> 0 | S3: =IF(R3*2.88/1000>Q3,R3*2.88/1000,Q3) -> 0 | V3: 0000 | W3: 0.3 | X3: 0.3 | Y3: NO | AD3: NO
B4: =IF(C4="PA",1,IF(C4="PB",2,IF(C4="PC",3,IF(C4="PD",4,IF(C4="PE",5,IF(C4="PF",6,IF(C4="PG",7,IF(C4="PH",8,IF(C4="PI",9,IF(C3="PJ",10,IF(C3="PK",11,IF(C3="PL",12,IF(C3="PM",13,IF(C3="PN",14,IF(C3="PO",15,IF(C3="PP",15,IF(C3="PQ",16,IF(C3="PR",17,0)))))))))))))))))) -> 1 | C4: PA | E4: =IMAGE(F4) -> #REF! | F4: https://drive.google.com/uc?export=view&id=1vcrZn_OLPxflHITc9KAVYfonNcP_7xys | I4: PZA | J4: 1 | K4: 1 | L4: =K4*J4 -> 1 | O4: =IF(AND(M4>0,N4>0),FALSE,IF(M4>0,M4*L4/6.65,N4*L4)) -> 0 | Q4: =P4*K4 -> 0 | S4: =IF(R4*2.88/1000>Q4,R4*2.88/1000,Q4) -> 0 | V4: 0000 | W4: 0.3 | X4: 0.3 | Y4: NO | AD4: NO
B5: =IF(C5="PA",1,IF(C5="PB",2,IF(C5="PC",3,IF(C5="PD",4,IF(C5="PE",5,IF(C5="PF",6,IF(C5="PG",7,IF(C5="PH",8,IF(C5="PI",9,IF(C3="PJ",10,IF(C3="PK",11,IF(C3="PL",12,IF(C3="PM",13,IF(C3="PN",14,IF(C3="PO",15,IF(C3="PP",15,IF(C3="PQ",16,IF(C3="PR",17,0)))))))))))))))))) -> 2 | C5: PB | E5: =IMAGE(F5) -> #REF! | F5: https://drive.google.com/uc?export=view&id=1vcrZn_OLPxflHITc9KAVYfonNcP_7xys | I5: PZA | J5: 1 | K5: 1 | L5: =K5*J5 -> 1 | O5: =IF(AND(M5>0,N5>0),FALSE,IF(M5>0,M5*L5/6.65,N5*L5)) -> 0 | Q5: =P5*K5 -> 0 | S5: =IF(R5*2.88/1000>Q5,R5*2.88/1000,Q5) -> 0 | V5: 0000 | W5: 0.3 | X5: 0.3 | Y5: NO | AD5: NO
K6: =SUM(CAJAS) -> 3 | L6: =SUM(L3:L5) -> 3 | M6: =SUM(M3:M5) -> 0 | N6: =SUM(N3:N5) -> 0 | O6: =SUM(TOTALUSD) -> 0 | Q6: =SUM(CBMTOTAL) -> 0 | R6: =SUM(PESO) -> 0 | S6: =SUM(PVOLUMETRICO) -> 0 | T6: =SUM(T3:T5) -> 0
A10: MODELO | C10: VALOR USD | D10: GASTOS INTERNOS EN CHINA | E10: FLETE MARITIMO | F10: SEGURO | G10: SALIDA DIVISAS ISD | H10: FLETE A YIWU | I10: COMISIÓN BANCARIA | J10: MONTACARGA | K10: TRANSPORTE ECUADOR | L10: ARANCEL | M10: FODINFA | N10: ICE/INEN | O10: IMPUESTOS ESPECIFICOS | P10: IVA | Q10: SERVICIOS LOGISTICOS | R10: GASTOS DE ADUANA | S10: CUSTODIA ARMADA Y CANDADO | T10: SEGURO DE TRANSPORTE INTERNO OPCIONAL | U10: TLC | V10: TAX (OPCIONAL)/OTROS VALORES | W10: TOTAL | X10: PRECIO UNITARIO | Y10: TOTAL FACTOR | Z10: PRECIO UNITARIO FACTOR | AA10: INCREMENTO TABLA | AB10: INCREMENTO FAC
A11: =D3 | C11: =+O3 -> 0 | D11: =$D$14*C11/$C$14 -> #DIV/0! | E11: =$E$14*C11/$C$14 -> #DIV/0! | F11: =+(C11+D11+E11)*1% -> #DIV/0! | G11: =+IF($D$18=TRUE,((D11+E11+F11+J11+V11)*5%),((C11+D11+E11+F11+H11+J11+V11)*5%)) -> #DIV/0! | H11: =T3 | I11: =C11*$I$14/$C$14 -> #DIV/0! | J11: =$J$14*C11/$C$14 -> #DIV/0! | K11: =$K$14*C11/$C$14 -> #DIV/0! | L11: =(C11+D11+F11+H11+J11+E11+Q11)*IF($D$19=TRUE,X3,W3) -> #DIV/0! | M11: =+(C11+E11+D11+F11+H11+J11+Q11)*0.5% -> #DIV/0! | N11: =(C11+D11+E11+F11+L11+M11+Q11)*(100%+Z3)*AA3 -> #DIV/0! | O11: =IF(Y3="IMPUESTOS ESPECIFICOS","IMP ESP",0) -> 0 | P11: =+(C11+D11+E11+F11+H11+I11+J11+L11+M11+N11+Q11+R11+S11+O11+U11+V11)*15% -> #DIV/0! | Q11: =C11*$Q$14/$C$14 -> #DIV/0! | R11: =C11*$R$14/$C$14 -> #DIV/0! | S11: =$S$14*C11/$C$14 -> #DIV/0! | T11: =(SUM(C11:S11)*0.6%) -> #DIV/0! | U11: =C11*$U$14/$C$14 -> #DIV/0! | V11: =$V$14*C11/$C$14 -> #DIV/0! | W11: =SUM(C11:V11) -> #DIV/0! | X11: =W11/L3 -> #DIV/0! | Y11: =C11*$Y$14/$C$14 -> #DIV/0! | Z11: =Y11/L3 -> #DIV/0! | AA11: =W11/O3-1 -> #DIV/0! | AB11: =Y11/O3-1 -> #DIV/0!
A12: =D4 | C12: =+O4 -> 0 | D12: =$D$14*C12/$C$14 -> #DIV/0! | E12: =$E$14*C12/$C$14 -> #DIV/0! | F12: =+(C12+D12+E12)*1% -> #DIV/0! | G12: =+IF($D$18=TRUE,((D12+E12+F12+J12+V12)*5%),((C12+D12+E12+F12+H12+J12+V12)*5%)) -> #DIV/0! | H12: =T4 | I12: =C12*$I$14/$C$14 -> #DIV/0! | J12: =$J$14*C12/$C$14 -> #DIV/0! | K12: =$K$14*C12/$C$14 -> #DIV/0! | L12: =(C12+D12+F12+H12+J12+E12+Q12)*IF($D$19=TRUE,X4,W4) -> #DIV/0! | M12: =+(C12+E12+D12+F12+H12+J12+Q12)*0.5% -> #DIV/0! | N12: =(C12+D12+E12+F12+L12+M12+Q12)*(100%+Z4)*AA4 -> #DIV/0! | O12: =IF(Y4="IMPUESTOS ESPECIFICOS","IMP ESP",0) -> 0 | P12: =+(C12+D12+E12+F12+H12+I12+J12+L12+M12+N12+Q12+R12+S12+O12+U12+V12)*15% -> #DIV/0! | Q12: =C12*$Q$14/$C$14 -> #DIV/0! | R12: =C12*$R$14/$C$14 -> #DIV/0! | S12: =$S$14*C12/$C$14 -> #DIV/0! | T12: =(SUM(C12:S12)*0.6%) -> #DIV/0! | U12: =C12*$U$14/$C$14 -> #DIV/0! | V12: =$V$14*C12/$C$14 -> #DIV/0! | W12: =SUM(C12:V12) -> #DIV/0! | X12: =W12/L4 -> #DIV/0! | Y12: =C12*$Y$14/$C$14 -> #DIV/0! | Z12: =Y12/L4 -> #DIV/0! | AA12: =W12/O4-1 -> #DIV/0! | AB12: =Y12/O4-1 -> #DIV/0!
A13: =D5 | C13: =+O5 -> 0 | D13: =$D$14*C13/$C$14 -> #DIV/0! | E13: =$E$14*C13/$C$14 -> #DIV/0! | F13: =+(C13+D13+E13)*1% -> #DIV/0! | G13: =+IF($D$18=TRUE,((D13+E13+F13+J13+V13)*5%),((C13+D13+E13+F13+H13+J13+V13)*5%)) -> #DIV/0! | H13: =T5 | I13: =C13*$I$14/$C$14 -> #DIV/0! | J13: =$J$14*C13/$C$14 -> #DIV/0! | K13: =$K$14*C13/$C$14 -> #DIV/0! | L13: =(C13+D13+F13+H13+J13+E13+Q13)*IF($D$19=TRUE,X5,W5) -> #DIV/0! | M13: =+(C13+E13+D13+F13+H13+J13+Q13)*0.5% -> #DIV/0! | N13: =(C13+D13+E13+F13+L13+M13+Q13)*(100%+Z5)*AA5 -> #DIV/0! | O13: =IF(Y5="IMPUESTOS ESPECIFICOS","IMP ESP",0) -> 0 | P13: =+(C13+D13+E13+F13+H13+I13+J13+L13+M13+N13+Q13+R13+S13+O13+U13+V13)*15% -> #DIV/0! | Q13: =C13*$Q$14/$C$14 -> #DIV/0! | R13: =C13*$R$14/$C$14 -> #DIV/0! | S13: =$S$14*C13/$C$14 -> #DIV/0! | T13: =(SUM(C13:S13)*0.6%) -> #DIV/0! | U13: =C13*$U$14/$C$14 -> #DIV/0! | V13: =$V$14*C13/$C$14 -> #DIV/0! | W13: =SUM(C13:V13) -> #DIV/0! | X13: =W13/L5 -> #DIV/0! | Y13: =C13*$Y$14/$C$14 -> #DIV/0! | Z13: =Y13/L5 -> #DIV/0! | AA13: =W13/O5-1 -> #DIV/0! | AB13: =Y13/O5-1 -> #DIV/0!
C14: =SUM(VALORUSD) -> 0 | D14: =S6*IF(S6<=3,$C$37,IF(S6<=12,$C$38,IF(S6<=21,$C$39,IF(S6>21,$C$40))))+D44 -> 0 | E14: =IF(S6<=3,S6*$E$37,IF(S6<=12,S6*$E$38,IF(S6<=21,S6*$E$39,IF(S6>21,S6*$E$40)))) -> 0 | F14: =SUM(SEGURO) -> #DIV/0! | G14: =SUM(ISD) -> #DIV/0! | H14: =SUM(FLETEYIWU) -> 0 | I14: =IF(D18=TRUE,((D14+E14+F14+V14)*3.5%),IF(O6<3000,(C14+D14+E14+F14+H14+V14)*3.5%,IF(N6>M6,140*D16,IF((C14+D14+E14+F14+H14+V14)*3.5%>140,140,(C14+D14+E14+F14+H14+V14)*3.5%)))) -> #DIV/0! | J14: =5.36*S6 -> 0 | K14: =IF(((70*S6)+K18)<10,10,(70*S6)+K18) -> 10 | L14: =SUM(L11:L13) -> #DIV/0! | M14: =SUM(M11:M13) -> #DIV/0! | N14: =SUM(ICE) -> #DIV/0! | O14: =SUM(O11:O13) -> 0 | P14: =SUM(IVA) -> #DIV/0! | Q14: =IF(C14>3000,(C14+D14+E14+F14)*IF(C14<I38,J37,IF(C14<I39,J38,IF(C14<I40,J39,IF(C14<I41,J40,IF(C14<I42,J41,IF(C14>=I42,IF(ISNUMBER(J42),J42,J41))))))),180) -> 180 | R14: =S6*IF(S6<=3,$D$37,IF(S6<=12,$D$38,IF(S6<=21,$D$39,IF(S6>21,$D$40))))+C14*IF(C14<I38,K37,IF(C14<I39,K38,IF(C14<I40,K39,IF(C14<I41,K40,IF(C14<I42,K41,IF(ISNUMBER(K42),K42,K41))))))+1 -> 1 | S14: =S6*IF(S6<=3,$F$37,IF(S6<=12,$F$38,IF(S6<=21,$F$39,IF(S6>21,$F$40)))) -> 0 | T14: =SUM(T11:T13) -> #DIV/0! | U14: =IF($D$19=TRUE,20,0) -> 0 | V14: =IF(SUM($O$3:$O$5)>3000,70,0) -> 0 | W14: =SUM(W11:W13) -> #DIV/0! | Y14: =IF(D30=TRUE,E30,IF(D31=TRUE,E31,IF(D32=TRUE,E32,0))) -> 0
C15: =IF(O6=C14," ","no coincide con TOTAL USD")
C16: PROV TOTALES | D16: =MAX(B3:B5) -> 2
C17: # DE PROVEEDORES PD | D17: 1
C18: PAGO DIRECTO | D18: FALSE | J18: TRANSPORTE | L18: SIN CUIDAD DE ENTREGA | N18: =ROUNDUP(S6,0)*1100/56 -> 0
C19: TLC | D19: FALSE
A20: LCL | C20: FLETE LCL | D20: 38
C21: EXW a FOB | D21: 0
C22: IMO | D22: FALSE
C23: VERIFICACION | D23: NO
C24: CANDADO | D24: NO
C25: NUMERO DE LEAD
C26: CBM TOTAL | D26: =Q6 -> 0
H27: Notificaciones
C28: LIQUIDACIÓN CORRECTA | E28: VALOR | F28: % | H28: =IF(C14>'3. LCL D'!B5,"PENDIENTE INCLUIR FILAS EN EL LCL","OK") -> OK
C29: TABLA | D29: FALSE | E29: =SUM(C11:V13) -> #DIV/0! | F29: =W14/(C14)-1 -> #DIV/0! | H29: =IF(C14=0,"OK",IF(I14>(D16*140),"ALERTA COMISION","OK")) -> OK
C30: FAC 1 | D30: FALSE | E30: ='b. LIQ.F'!F82 -> #DIV/0! | F30: ='2.FAC'!W16/(C14)-1 -> #DIV/0! | G30: =E30-C14 -> #DIV/0! | H30: =IF(C14=0,"OK", IF(S6=0,"CBM=0",IF(S6<Q6, "ERROR DE CBM / PESO","OK"))) -> OK
C31: FAC 2 | D31: FALSE | E31: ='b. LIQ.F'!N82 -> #DIV/0! | F31: ='2.FAC'!W21/(C14)-1 -> #DIV/0! | H31: =IF(C14=0,"OK", IF(E29=SUM(C14:V14),"OK","NO COINCIDE LOS TOTALES")) -> OK
C32: FAC 3 | D32: FALSE | E32: ='b. LIQ.F'!V82 -> #DIV/0! | F32: ='2.FAC'!W26/(C14)-1 -> #DIV/0! | H32: =IF(C14=0,"OK", IF(L18="SIN CIUDAD DE ENTREGA","SIN CIUDAD DE ENTREGA","OK")) -> OK
C33: LCL | D33: FALSE | E33: ='3. LCL D'!U7 -> #DIV/0! | F33: =E33/(C14)-1 -> #DIV/0! | H33: =IF(C15=0,"OK", IF(L19="SIN CIUDAD DE ENTREGA","SIN CIUDAD DE ENTREGA","OK")) -> OK
H34: =IF(D25=0,"NUMERO DE LEAD"," ") -> NUMERO DE LEAD
A35: COSTOS BASADOS EN CBM | H35: COSTOS BASADOS EN MONTO EN CHINA
A36: CBM | C36: GASTOS INTERNOS EN CHINA | D36: GASTOS DE ADUANA | E36: FLETE MARÍTIMO | F36: CANDADO SATELITAL | H36: USD CHINA | I36: MIN USD CHINA | J36: % SERVICIOS LOGÍSTICOS | K36: % GASTOS DE ADUANA
A37: 0-3 | C37: 53.57 | D37: 50 | E37: 120 | F37: 12 | H37: 0-5000 | I37: 0 | J37: 0.06 | K37: 0.03
A38: 3.1-12 | C38: 45 | D38: 45 | E38: 90 | F38: 11 | H38: 5000-10000 | I38: 5000 | J38: 0.06 | K38: 0.02
A39: 12.1-21 | C39: 37.5 | D39: 40 | E39: 78 | F39: 10 | H39: 10000-15000 | I39: 10000 | J39: 0.06 | K39: 0.0066666667
A40: 21.1-30 | C40: 30 | D40: 35 | E40: 65 | F40: 9 | H40: 15000-20000 | I40: 15000 | J40: 0.06 | K40: 0.005
H41: 20000-30000 | I41: 20000 | J41: 0.06 | K41: 0.0033
A42: VALORES EXTRAS PAGOS DIRECTOS | H42: 30000 o más | I42: 30000 | J42: CONSULTAR | K42: CONSULTAR
A43: # DE PROVEEDORES | C43: COORDINACION EN BODEGA | D43: VALOR CALCULADO
A44: TODOS | C44: 10 | D44: =IF(D18=TRUE,IF(D17=0,"ERROR",D17*C44),0) -> 0

Sheet 3. LCL D
A1: MODELO | B1: VALOR USD | C1: COSTO DE EXPORTACION (EXW A FOB) | D1: FLETE MARITIMO | E1: SEGURO | F1: SALIDA DIVISAS ISD | G1: COMISIÓN BANCARIA (2 X PROVEEDOR) | H1: ="VERIFICACION DEL PROVEEDOR"&" "&'1.CÁL'!D23 -> VERIFICACION DEL PROVEEDOR NO | I1: TLC (OPCIONAL) | J1: AD-VALOREM | K1: FODINFA | L1: ICE | M1: IMPUESTOS ESPECIFICOS | N1: IVA SENAE | O1: SERVICIOS LOGISTICOS | P1: GASTOS LOCALES | Q1: AGENTE DE ADUANA | R1: DEPOSITO TEMPORAL | S1: TRANSPORTE INTERNO ECUADOR | T1: CANDADO | U1: TOTAL | V1: PRECIO UNITARIO
A2: ='1.CÁL'!D3 | B2: ='1.CÁL'!O3 -> 0 | C2: =B2*$C$5/$B$5 -> #DIV/0! | D2: =B2*$D$5/$B$5 -> #DIV/0! | E2: =B2*$E$5/$B$5 -> #DIV/0! | F2: =B2*$F$5/$B$5 -> #DIV/0! | G2: =B2*$G$5/$B$5 -> #DIV/0! | H2: =B2*$H$5/$B$5 -> #DIV/0! | I2: =B2*$I$5/$B$5 -> #DIV/0! | J2: =(B2+C2+E2+D2)*'1.CÁL'!W3 -> #DIV/0! | K2: =+(B2+D2+C2+E2)*0.5% -> #DIV/0! | L2: =(B2+C2+D2+E2+J2+K2)*(100%+'1.CÁL'!Z3)*'1.CÁL'!AA3 -> #DIV/0! | M2: ='1.CÁL'!O11 -> 0 | N2: =+(B2+C2+D2+E2+J2+K2+L2+M2)*15% -> #DIV/0! | O2: =B2*$O$5/$B$5 -> #DIV/0! | P2: =B2*$P$5/$B$5 -> #DIV/0! | Q2: =B2*$Q$5/$B$5 -> #DIV/0! | R2: =B2*$R$5/$B$5 -> #DIV/0! | S2: =B2*$S$5/$B$5 -> #DIV/0! | T2: =B2*$T$5/$B$5 -> #DIV/0! | U2: =SUM(B2:T2) -> #DIV/0! | V2: =U2/'1.CÁL'!L3 -> #DIV/0!
A3: ='1.CÁL'!D4 | B3: ='1.CÁL'!O4 -> 0 | C3: =B3*$C$5/$B$5 -> #DIV/0! | D3: =B3*$D$5/$B$5 -> #DIV/0! | E3: =B3*$E$5/$B$5 -> #DIV/0! | F3: =B3*$F$5/$B$5 -> #DIV/0! | G3: =B3*$G$5/$B$5 -> #DIV/0! | H3: =B3*$H$5/$B$5 -> #DIV/0! | I3: =B3*$I$5/$B$5 -> #DIV/0! | J3: =(B3+C3+E3+D3)*'1.CÁL'!W4 -> #DIV/0! | K3: =+(B3+D3+C3+E3)*0.5% -> #DIV/0! | L3: =(B3+C3+D3+E3+J3+K3)*(100%+'1.CÁL'!Z4)*'1.CÁL'!AA4 -> #DIV/0! | M3: ='1.CÁL'!O12 -> 0 | N3: =+(B3+C3+D3+E3+J3+K3+L3+M3)*15% -> #DIV/0! | O3: =B3*$O$5/$B$5 -> #DIV/0! | P3: =B3*$P$5/$B$5 -> #DIV/0! | Q3: =B3*$Q$5/$B$5 -> #DIV/0! | R3: =B3*$R$5/$B$5 -> #DIV/0! | S3: =B3*$S$5/$B$5 -> #DIV/0! | T3: =B3*$T$5/$B$5 -> #DIV/0! | U3: =SUM(B3:T3) -> #DIV/0! | V3: =U3/'1.CÁL'!L4 -> #DIV/0!
A4: ='1.CÁL'!D5 | B4: ='1.CÁL'!O5 -> 0 | C4: =B4*$C$5/$B$5 -> #DIV/0! | D4: =B4*$D$5/$B$5 -> #DIV/0! | E4: =B4*$E$5/$B$5 -> #DIV/0! | F4: =B4*$F$5/$B$5 -> #DIV/0! | G4: =B4*$G$5/$B$5 -> #DIV/0! | H4: =B4*$H$5/$B$5 -> #DIV/0! | I4: =B4*$I$5/$B$5 -> #DIV/0! | J4: =(B4+C4+E4+D4)*'1.CÁL'!W5 -> #DIV/0! | K4: =+(B4+D4+C4+E4)*0.5% -> #DIV/0! | L4: =(B4+C4+D4+E4+J4+K4)*(100%+'1.CÁL'!Z5)*'1.CÁL'!AA5 -> #DIV/0! | M4: ='1.CÁL'!O13 -> 0 | N4: =+(B4+C4+D4+E4+J4+K4+L4+M4)*15% -> #DIV/0! | O4: =B4*$O$5/$B$5 -> #DIV/0! | P4: =B4*$P$5/$B$5 -> #DIV/0! | Q4: =B4*$Q$5/$B$5 -> #DIV/0! | R4: =B4*$R$5/$B$5 -> #DIV/0! | S4: =B4*$S$5/$B$5 -> #DIV/0! | T4: =B4*$T$5/$B$5 -> #DIV/0! | U4: =SUM(B4:T4) -> #DIV/0! | V4: =U4/'1.CÁL'!L5 -> #DIV/0!
A5: Subtotal | B5: =SUM(B2:B4) -> 0 | C5: ='1.CÁL'!D21 -> 0 | D5: =IF('1.CÁL'!S6 <1, C12, C12*'1.CÁL'!S6) -> 41 | E5: =IF((B5+C5+D5)*C20>E20,(B5+C5+D5)*C20,E20) -> 30 | F5: =(B5+C5+D5)*5% -> 2.05 | G5: =B22*'1.CÁL'!D17 -> 140 | H5: =IF('1.CÁL'!D23="FISICA",450,IF('1.CÁL'!D23="DOCUMENTAL",50,0)) -> 0 | I5: =IF('1.CÁL'!D19=TRUE,C23,0) -> 0 | J5: =SUM(J2:J4) -> #DIV/0! | K5: =SUM(K2:K4) -> #DIV/0! | L5: =SUM(ICE) -> #DIV/0! | M5: =SUM(M2:M4) -> 0 | N5: =SUM(N2:N4) -> #DIV/0! | O5: =IF(B5>3000,(B5+C5+D5+E5)*IF(B5<'1.CÁL'!I38,'1.CÁL'!J37,IF(B5<'1.CÁL'!I39,'1.CÁL'!J38,IF(B5<'1.CÁL'!I40,'1.CÁL'!J39,IF(B5<'1.CÁL'!I41,'1.CÁL'!J40,IF(B5<'1.CÁL'!I42,'1.CÁL'!J41,IF(B5>='1.CÁL'!I42,IF(ISNUMBER('1.CÁL'!J42),'1.CÁL'!J42,'1.CÁL'!J41))))))),180) -> 180 | P5: =B32 -> 380 | Q5: =C24*'1.CÁL'!D17 -> 280 | R5: =F41 -> 43.57 | S5: =IF(((70*'1.CÁL'!S6)+'1.CÁL'!K18)<10,10,(70*'1.CÁL'!S6)+'1.CÁL'!K18) -> 10 | T5: =IF('1.CÁL'!D24="SI",150/1.15,0) -> 0 | U5: =SUM(B5:T5) -> #DIV/0!
A6: IVA | B6: =B5*0% -> 0 | C6: =C5*0% -> 0 | D6: =D5*0% -> 0 | E6: =E5*15% -> 4.5 | F6: =F5*0% -> 0 | G6: =G5*15% -> 21 | H6: =H5*15% -> 0 | I6: =I5*15% -> 0 | J6: =J5*0% -> #DIV/0! | K6: =K5*0% -> #DIV/0! | L6: =L5*0% -> #DIV/0! | M6: =M5*0% -> 0 | N6: =N5*0% -> #DIV/0! | O6: =O5*15% -> 27 | P6: =P5*15% -> 57 | Q6: =Q5*15% -> 42 | R6: =R5*15% -> 6.5355 | S6: =S5*0% -> 0 | T6: =T5*15% -> 0 | U6: =SUM(B6:T6) -> #DIV/0!
A7: Total | B7: =SUM(B5:B6) -> 0 | C7: =SUM(C5:C6) -> 0 | D7: =SUM(D5:D6) -> 41 | E7: =SUM(E5:E6) -> 34.5 | F7: =SUM(F5:F6) -> 2.05 | G7: =SUM(G5:G6) -> 161 | H7: =SUM(H5:H6) -> 0 | I7: =SUM(I5:I6) -> 0 | ... U7: =SUM(U5:U6) -> #DIV/0!
A10: TARIFAS
A11: Rubro | B11: PVP | C11: PVP NCESCH | D11: Mínimo | E11: Mín NCESCH | F11: Base | G11: IVA
A12: Flete | B12: ='1.CÁL'!D20 -> 38 | C12: =B12+3 -> 41 | D12: 0 | E12: 0 | F12: W/M | G12: 0
A13: S. Logístico | B13: 28 | C13: =B13+5 -> 33 | D13: 150 | E13: 150 | F13: W/M | G13: 0.15
A14: S. Portuario | B14: 10 | C14: 13 | D14: 50 | E14: 55 | F14: W/M | G14: 0.15
A15: Administración | B15: 100 | C15: 105 | D15: 0 | E15: 0 | F15: BL | G15: 0.15
A16: Transmisión | B16: 20 | C16: 25 | D16: 0 | E16: 0 | F16: BL | G16: 0.15
A17: Sello y Pesaje | B17: 20 | C17: 25 | D17: 0 | E17: 0 | F17: BL | G17: 0.15
A18: Cobranza | B18: 0 | C18: =B18*1.1 -> 0 | D18: 0 | E18: 0 | F18: BL | G18: 0.15
A19: IMO | B19: 60 | C19: 70 | D19: 0 | E19: 0 | F19: BL | G19: 0.15
A20: Seguro | B20: 0.0015 | C20: 0.005 | D20: 25 | E20: 30 | F20: BL | G20: 0.15
A21: Manejo Local | B21: 0.06 | C21: 0.06 | D21: 15 | E21: 20 | F21: BL | G21: 0.15
A22: C. Bancaria | B22: 140 | C22: =B22 -> 140 | D22: 0 | E22: 0 | F22: BL | G22: 0.15
A23: TLC | B23: 0 | C23: =B23 -> 0 | D23: 0 | E23: 0 | F23: BL | G23: 0.15
A24: Agente | B24: 280 | C24: =B24 -> 280 | D24: 0 | E24: 0 | F24: BL | G24: 0.15
C27: IVA | D27: Total
A28: W/M | B28: =IF('1.CÁL'!Q6*C13>E13,'1.CÁL'!Q6*C13,E13)+IF('1.CÁL'!Q6*C14>E14,'1.CÁL'!Q6*C14,E14) -> 205 | C28: =B28*15% -> 30.75 | D28: =SUM(B28:C28) -> 235.75
A29: BL | B29: =C15+C16+C17 -> 155 | C29: =B29*15% -> 23.25 | D29: =SUM(B29:C29) -> 178.25
A30: IMO | B30: =IF('1.CÁL'!D22=TRUE,C19,0) -> 0 | C30: =B30*15% -> 0 | D30: =SUM(B30:C30) -> 0
A31: Manejo Local | B31: =IF(SUM(C5:D5)*6%>E21,SUM(C5:D5)*6%,E21) -> 20 | C31: =B31*15% -> 3 | D31: =SUM(B31:C31) -> 23
A32: Subtotal | B32: =SUM(B28:B31) -> 380 | C32: =SUM(C28:C31) -> 57 | D32: =SUM(D28:D31) -> 437
A35: Bodega | B35: PVP | C35: Mínimo | D35: Base | E35: IVA | F35: Subtotal
A36: Almacenaje | B36: 2.2 | C36: 22.11 | D36: W/M | E36: 0.15 | F36: =IF(B36*'1.CÁL'!S6*7>C36,B36*'1.CÁL'!S6*7,C36) -> 22.11
A37: Handling para aforo | B37: 2.08 | D37: W/M | E37: 0.15 | F37: =B37*'1.CÁL'!S6 -> 0
A38: Cuadrilla para aforo (1 a 100 bultos) | B38: 21.46 | D38: BL | E38: 0.15 | F38: =B38 -> 21.46
A39: Despacho carga general | B39: 4.32 | D39: W/M | E39: 0.15 | F39: =B39*'1.CÁL'!S6 -> 0
A40: Servicio de tarja | B40: 16.59 | D40: W/M | E40: 0.15 | F40: =B40*'1.CÁL'!S6 -> 0
F41: =SUM(F36:F40) -> 43.57

Sheet 2.FAC
D2: VALOR | E2: ='1.CÁL'!O6 -> 0 | F2: USD
D3: # CAJAS | E3: =CAJAS1 -> 3
D4: W/M | E4: ='1.CÁL'!S6 -> 0 | F4: M3
D5: FLETE YIWU | E5: =FLETEYIWU1 -> 0 | F5: $
D7: FACTOR | E7: =+IF($V$16>2.3,IF($V$21>2.3,$V$26,$V$21),$V$16) -> #DIV/0!
D8: SERVICIO | E8: =+E2*(E7-1) -> #DIV/0!
D9: TOTAL | E9: =E2*E7 -> #DIV/0!
D10: TRANSPORTE | E10: ='1.CÁL'!K18 | F10: ='1.CÁL'!L18 -> SIN CUIDAD DE ENTREGA
D14: GI | E14: FM | F14: S | G14: ISD | H14: FY | I14: CM | J14: M | K14: TE | L14: A F | P14: I | Q14: SL | R14: GA | S14: CS
C15: VALOR USD | D15: GASTOS INTERNOS EN CHINA | E15: FLETE MARITIMO | F15: SEGURO | G15: SALIDA DIVISAS | H15: FLETE A YIWU | I15: COMSION BANCARIO | J15: MONTACARGAS | K15: TRANSPORTE ECUADOR | L15: ARANCEL | M15: FODINFA | N15: ICE/INEN | O15: IMPUESTOS ESPECIFICOS | P15: IVA | Q15: SERVICIO LOGISTICO | R15: GASTOS DE ADUANA | S15: CUSTODIA ARMADA Y CANDADO | T15: SEGURO DE TRANSPORTE INTERNO OPCIONAL | U15: TOTAL | V15: FACTOR | W15: TOTAL CON SEGURO
C16: =+'2.FAC'!$E$2 -> 0 | D16: =$D$30*'2.FAC'!$E$4/D45 -> 0 | E16: =$D$31*'2.FAC'!$E$4/D45 -> 0 | F16: =+('2.FAC'!$E$2+D16+E16)*$D$36 -> 0 | G16: =+(D16+E16+F16+H16+C16+J16)*$D$37 -> 0 | H16: ='2.FAC'!E5 -> 0 | I16: =+C16*3.5% -> 0 | J16: =$D$32*'2.FAC'!$E$4/D45 -> 0 | K16: =IF(($D$33*'2.FAC'!$E$4/D45+E10)<10,10,$D$33*'2.FAC'!$E$4/D45+E10) -> 10 | L16: =+('2.FAC'!$E$2+D16+F16+S16+H16+J16+E16+Q16)*($D$38) -> 1.8 | M16: =+('2.FAC'!$E$2+E16+D16+F16+S16+H16+J16+Q16)*($D$39) -> 0.03 | N16: ='1.CÁL'!N14 -> #DIV/0! | O16: ='1.CÁL'!O14 -> 0 | P16: =+('2.FAC'!$E$2+D16+E16+F16+L16+M16+S16+J16+R16+Q16+H16)*$D$41 -> 1.1745 | Q16: =$D$40*('2.FAC'!$E$2+D16+E16+F16)+1 -> 1 | R16: =$D$35*'2.FAC'!$E$4/D45+2%*('2.FAC'!$E$2) -> 0 | S16: =IF($D$34*'2.FAC'!$E$4/D45<5,5,$D$34*'2.FAC'!$E$4/D45) -> 5 | T16: =U16*0.6% -> #DIV/0! | U16: =SUM(C16:S16) -> #DIV/0! | V16: =+W16/C16 -> #DIV/0! | W16: =U16+T16 -> #DIV/0!
A17: PRORRATEO | B17: =E2+E5 -> 0 | D17: ='1.CÁL'!D14*$B$18/SUM('1.CÁL'!$D$14:$V$14) -> #DIV/0! | E17: ='1.CÁL'!E14*$B$18/SUM('1.CÁL'!$D$14:$V$14) -> #DIV/0! | F17: ='1.CÁL'!F14*$B$18/SUM('1.CÁL'!$D$14:$V$14) -> #DIV/0! | G17: ='1.CÁL'!G14*$B$18/SUM('1.CÁL'!$D$14:$V$14) -> #DIV/0! | H17: ='1.CÁL'!H14*$B$18/SUM('1.CÁL'!$D$14:$V$14) -> #DIV/0! | I17: ='1.CÁL'!I14*$B$18/SUM('1.CÁL'!$D$14:$V$14) -> #DIV/0! | J17: ='1.CÁL'!J14*$B$18/SUM('1.CÁL'!$D$14:$V$14) -> #DIV/0! | K17: ='1.CÁL'!K14*$B$18/SUM('1.CÁL'!$D$14:$V$14) -> #DIV/0! | ... Q17: ='1.CÁL'!Q14*$B$18/SUM('1.CÁL'!$D$14:$V$14) -> #DIV/0! | R17: =('1.CÁL'!R14+'1.CÁL'!U14+'1.CÁL'!V14)*$B$18/SUM('1.CÁL'!$D$14:$V$14) -> #DIV/0! | S17: ='1.CÁL'!S14*$B$18/SUM('1.CÁL'!$D$14:$V$14) -> #DIV/0! | T17: ='1.CÁL'!T14*$B$18/SUM('1.CÁL'!$D$14:$V$14) -> #DIV/0!
B18: =D16+E16+F16+G16+I16+J16+K16+L16+M16+P16+Q16+R16+N16+O16+S16+T16 -> #DIV/0!
D19: GI | E19: FM | F19: S | G19: ISD | H19: FY | I19: CM | J19: M | K19: TE | L19: A F | P19: I | Q19: SL | R19: GA | S19: CS
C20: VALOR USD | D20: GASTOS INTERNOS EN CHINA | E20: FLETE MARITIMO | F20: SEGURO | G20: SALIDA DIVISAS | H20: FLETE A YIWU | I20: COMSION BANCARIO | J20: MONTACARGAS | K20: TRANSPORTE ECUADOR | L20: ARANCEL | M20: FODINFA | N20: ICE/INEN | O20: IMPUESTOS ESPECIFICOS | P20: IVA | Q20: SERVICIO LOGISTICO | R20: GASTOS DE ADUANA | S20: CUSTODIA ARMADA Y CANDADO | T20: SEGURO DE TRANSPORTE INTERNO OPCIONAL | U20: TOTAL | V20: FACTOR | W20: TOTAL CON SEGURO
C21: =+'2.FAC'!$E$2 -> 0 | D21: =$D$30*'2.FAC'!$E$4/D46 -> 0 | E21: =$D$31*'2.FAC'!$E$4/D46 -> 0 | F21: =+('2.FAC'!$E$2+D21+E21)*$D$36 -> 0 | G21: =+(D21+E21+F21+H21+C21+J21)*$D$37 -> 0 | H21: =+'2.FAC'!$E$5 -> 0 | I21: =+C21*3.5% -> 0 | J21: =$D$32*'2.FAC'!$E$4/D46 -> 0 | K21: =IF(($D$33*'2.FAC'!$E$4/D46+E10)<10,10,$D$33*'2.FAC'!$E$4/D46+E10) -> 10 | L21: =+('2.FAC'!$E$2+D21+F21+S21+H21+J21+E21+Q21)*($D$38) -> 1.8 | M21: =+('2.FAC'!$E$2+D21+E21+F21+S21+H21+J21+Q21)*($D$39) -> 0.03 | N21: ='1.CÁL'!N14 -> #DIV/0! | O21: ='1.CÁL'!O14 -> 0 | P21: =+('2.FAC'!$E$2+D21+E21+F21+L21+M21+S21+J21+R21+Q21+H21)*$D$41 -> 1.1745 | Q21: =$D$40*('2.FAC'!$E$2+D21+E21+F21)+1 -> 1 | R21: =$D$35*'2.FAC'!$E$4/D46+2%*('2.FAC'!$E$2) -> 0 | S21: =IF($D$34*'2.FAC'!$E$4/D46<5,5,$D$34*'2.FAC'!$E$4/D46) -> 5 | T21: =U21*0.6% -> #DIV/0! | U21: =SUM(C21:S21) -> #DIV/0! | V21: =+W21/C21 -> #DIV/0! | W21: =U21+T21 -> #DIV/0!
A22: PRORRATEO | B22: =E2+E5 -> 0 | D22: ='1.CÁL'!D14*$B$23/SUM('1.CÁL'!$D$14:$V$14) -> #DIV/0! | E22: ='1.CÁL'!E14*$B$23/SUM('1.CÁL'!$D$14:$V$14) -> #DIV/0! | F22: ='1.CÁL'!F14*$B$23/SUM('1.CÁL'!$D$14:$V$14) -> #DIV/0! | G22: ='1.CÁL'!G14*$B$23/SUM('1.CÁL'!$D$14:$V$14) -> #DIV/0! | H22: ='1.CÁL'!H14*$B$23/SUM('1.CÁL'!$D$14:$V$14) -> #DIV/0! | I22: ='1.CÁL'!I14*$B$23/SUM('1.CÁL'!$D$14:$V$14) -> #DIV/0! | J22: ='1.CÁL'!J14*$B$23/SUM('1.CÁL'!$D$14:$V$14) -> #DIV/0! | K22: ='1.CÁL'!K14*$B$23/SUM('1.CÁL'!$D$14:$V$14) -> #DIV/0! | ... Q22: ='1.CÁL'!Q14*$B$23/SUM('1.CÁL'!$D$14:$V$14) -> #DIV/0! | R22: =('1.CÁL'!R14+'1.CÁL'!U14+'1.CÁL'!V14)*$B$23/SUM('1.CÁL'!$D$14:$V$14) -> #DIV/0! | S22: ='1.CÁL'!S14*$B$23/SUM('1.CÁL'!$D$14:$V$14) -> #DIV/0! | T22: ='1.CÁL'!T14*$B$23/SUM('1.CÁL'!$D$14:$V$14) -> #DIV/0!
B23: =D21+E21+F21+G21+I21+J21+K21+L21+M21+N21+O21+P21+Q21+R21+S21+T21 -> #DIV/0!
D24: GI | E24: FM | F24: S | G24: ISD | H24: FY | I24: CM | J24: M | K24: TE | L24: A F | P24: I | Q24: SL | R24: GA | S24: CS
C25: VALOR USD | D25: GASTOS INTERNOS EN CHINA | E25: FLETE MARITIMO | F25: SEGURO | G25: SALIDA DIVISAS | H25: FLETE A YIWU | I25: COMSION BANCARIO | J25: MONTACARGAS | K25: TRANSPORTE ECUADOR | L25: ARANCEL | M25: FODINFA | N25: ICE/INEN | O25: IMPUESTOS ESPECIFICOS | P25: IVA | Q25: SERVICIO LOGISTICO | R25: GASTOS DE ADUANA | S25: CUSTODIA ARMADA Y CANDADO | T25: SEGURO DE TRANSPORTE INTERNO OPCIONAL | U25: TOTAL | V25: FACTOR | W25: TOTAL CON SEGURO
C26: =+'2.FAC'!$E$2 -> 0 | D26: =$D$30*'2.FAC'!$E$4/D47 -> 0 | E26: =$D$31*'2.FAC'!$E$4/D47 -> 0 | F26: =+('2.FAC'!$E$2+D26+E26)*$D$36 -> 0 | G26: =+(D26+E26+F26+H26+C26+J26)*$D$37 -> 0 | H26: =+'2.FAC'!$E$5 -> 0 | I26: =+C26*3.5% -> 0 | J26: =$D$32*'2.FAC'!$E$4/D47 -> 0 | K26: =IF(($D$33*'2.FAC'!$E$4/D47+E10)<10,10,$D$33*'2.FAC'!$E$4/D47+E10) -> 10 | L26: =+('2.FAC'!$E$2+D26+F26+S26+H26+J26+E26+Q26)*($D$38) -> 1.8 | M26: =+('2.FAC'!$E$2+E26+D26+F26+S26+H26+J26+Q26)*($D$39) -> 0.03 | N26: ='1.CÁL'!N14 -> #DIV/0! | O26: ='1.CÁL'!O14 -> 0 | P26: =+('2.FAC'!$E$2+D26+E26+F26+L26+M26+S26+J26+R26+Q26+H26)*$D$41 -> 1.1745 | Q26: =$D$40*('2.FAC'!$E$2+D26+E26+F26)+1 -> 1 | R26: =$D$35*'2.FAC'!$E$4/D47+2%*('2.FAC'!$E$2) -> 0 | S26: =IF($D$34*'2.FAC'!$E$4/D47<5,5,$D$34*'2.FAC'!$E$4/D47) -> 5 | T26: =U26*0.6% -> #DIV/0! | U26: =SUM(C26:S26) -> #DIV/0! | V26: =+W26/C26 -> #DIV/0! | W26: =U26+T26 -> #DIV/0!
A27: PRORRATEO | B27: =E2+E5 -> 0 | D27: ='1.CÁL'!D14*$B$28/SUM('1.CÁL'!$D$14:$V$14) -> #DIV/0! | E27: ='1.CÁL'!E14*$B$28/SUM('1.CÁL'!$D$14:$V$14) -> #DIV/0! | F27: ='1.CÁL'!F14*$B$28/SUM('1.CÁL'!$D$14:$V$14) -> #DIV/0! | G27: ='1.CÁL'!G14*$B$28/SUM('1.CÁL'!$D$14:$V$14) -> #DIV/0! | H27: ='1.CÁL'!H14*$B$28/SUM('1.CÁL'!$D$14:$V$14) -> #DIV/0! | I27: ='1.CÁL'!I14*$B$28/SUM('1.CÁL'!$D$14:$V$14) -> #DIV/0! | J27: ='1.CÁL'!J14*$B$28/SUM('1.CÁL'!$D$14:$V$14) -> #DIV/0! | K27: ='1.CÁL'!K14*$B$28/SUM('1.CÁL'!$D$14:$V$14) -> #DIV/0! | ... Q27: ='1.CÁL'!Q14*$B$28/SUM('1.CÁL'!$D$14:$V$14) -> #DIV/0! | R27: =('1.CÁL'!R14+'1.CÁL'!U14+'1.CÁL'!V14)*$B$28/SUM('1.CÁL'!$D$14:$V$14) -> #DIV/0! | S27: ='1.CÁL'!S14*$B$28/SUM('1.CÁL'!$D$14:$V$14) -> #DIV/0! | T27: ='1.CÁL'!T14*$B$28/SUM('1.CÁL'!$D$14:$V$14) -> #DIV/0!
B28: =D26+E26+F26+G26+I26+J26+K26+L26+M26+N26+O26+P26+Q26+R26+S26+T26 -> #DIV/0!
C30: FLETE INTERNO | D30: 1500 | E30: $
C31: FLETE MARITIMO | D31: 2520 | E31: $
C32: MONTACARGAS | D32: 112 | E32: $
C33: FLETE ECUADOR | D33: 1960 | E33: $
C34: CANDADO | D34: 325 | E34: $
C35: BASE ADUANA | D35: 1400 | E35: $
C36: SEGURO | D36: 0.01 | E36: %
C37: ISD | D37: 0.05 | E37: %
C38: ARANCEL | D38: 0.3 | E38: %
C39: FONDINFA | D39: 0.005 | E39: % | J39: `
C40: SERVICIO | D40: 0.06 | E40: %
C41: IVA | D41: 0.15 | E41: %
C42: PESO | D42: 100 | E42: Kg
C45: BASE CBM | D45: 28 | E45: =$D$31/D45 -> 90
C46: BASE CBM | D46: 32 | E46: =$D$31/D46 -> 78.75
C47: BASE CBM | D47: 36 | E47: =$D$31/D47 -> 70
C48: TOPE COMPRA | D48: 3000

Sheet a.1 LIQ PD
B2: =IF(OR('1.CÁL'!$D$29=TRUE,'1.CÁL'!$F$29="OK"),"LIQUIDACIÓN CORRECTA","NO VÁLIDA") -> #DIV/0!
B3: NEGOCIOS CESCH CIA.LTDA.
B5: Vendedor:
B6: Fecha: | D6: =TODAY() -> 46181
B7: Datos del cliente
B8: Nombre:
B9: CI o RUC:
B10: Dirección:
B11: Ciudad de entrega:
B12: Número de teléfono: | E12: CBM: | F12: ='1.CÁL'!Q6/1.1 -> 0
B13: Email: | E13: Cantidad de caja: | F13: ='1.CÁL'!K6 -> 3
B14: No. Doc Cotización: | E14: Peso: | F14: ='1.CÁL'!R6 -> 0
B15: Item | D15: Detalle | E15: Total
B16: 1 | D16: Valor de la Mercadería | E16: ='1.CÁL'!C14+'1.CÁL'!T6 -> 0
B17: 2 | D17: Gastos Internos en China | E17: ='1.CÁL'!D14+'1.CÁL'!J14 -> 0
B18: 3 | D18: Flete Marítimo | E18: ='1.CÁL'!E14 -> 0
B19: 4 | D19: Seguro | E19: ='1.CÁL'!F14 -> #DIV/0!
B20: 5 | D20: Comisión Bancaria | E20: ='1.CÁL'!I14 -> #DIV/0!
B21: 6 | D21: Transporte Ecuador (dirección acordada) | E21: ='1.CÁL'!K14 -> 10
B22: 7 | D22: Arancel + 0.5% FODINFA | E22: ='1.CÁL'!M14+'1.CÁL'!L14 -> #DIV/0!
B23: 8 | D23: Impuesto Específico | E23: ='1.CÁL'!O14 -> 0
B24: 9 | D24: Servicios Logísticos | E24: ='1.CÁL'!Q14 -> 180
B25: 10 | D25: Gastos de Aduana | E25: ='1.CÁL'!R14 -> 1
B26: 11 | D26: Custodia Armada y Candado | E26: ='1.CÁL'!S14 -> 0
B27: 12 | D27: Tax (Opcional) | E27: ='1.CÁL'!V14 -> 0
B28: 13 | D28: Certificado de origen | E28: ='1.CÁL'!U14 -> 0
B29: 14 | D29: ICE/INEN | E29: ='1.CÁL'!N14 -> #DIV/0!
B30: 15 | D30: PRECIO FINAL EN ECUADOR | E30: =SUM(E16:F29)+F40 -> #DIV/0!
B31: 16 | D31: IVA | E31: ='1.CÁL'!P14 -> #DIV/0!
B32: 17 | D32: Salida Divisas ISD | E32: ='1.CÁL'!G14 -> #DIV/0!
D33: TOTAL | E33: =SUM(E30:F32) -> #DIV/0!
B34: *En pago al contado (transferencia, depósito, efectivo), se otorga un descuento al cliente* | E34: Valor | F34: Pago al contado incluido descuento
E35: =F35*1.055 -> #DIV/0! | F35: =E33 -> #DIV/0! | G35: =IF(F35=F66,"","no coinciden") -> #DIV/0!
B36: Pago 1 PAGO DIRECTO AL PROVEEDOR | E36: =F36*1.055 -> 0 | F36: =E16 -> 0
B37: Pago 2 PAGO PARA CARGAR EN CHINA | E37: =F37*1.055 -> #DIV/0! | F37: =F35-F36-F38 -> #DIV/0!
B38: Pago 3 PAGO PARA NACIONALIZAR EN ECUADOR | E38: =F38*1.055 -> #DIV/0! | F38: =+E21+E22+E23+E25+E26+E31+F40+E27+E29+E28+(E24*50%) -> #DIV/0!
B39: Observaciones :
B40: Seguro de transporte interno (opcional) | E40: 0.006 | F40: ='1.CÁL'!T14 -> #DIV/0!
B41: *La liquidación presentada al cliente se basa en la información proporcionada por el proveedor; la cual podría ser actualizada en caso de existir alguna variación en precios de los productos, flete o CBM*
B42: *La tarifa de flete marítimo esta cotizada a la semana actual, podrá varíar si existe cambios en las tarifas generales de flete marítimo.
...

Sheet a.LIQ
B2: =IF(OR('1.CÁL'!$D$29=TRUE,'1.CÁL'!$F$29="OK"),"LIQUIDACIÓN CORRECTA","NO VÁLIDA") -> #DIV/0!
B3: NEGOCIOS CESCH CIA.LTDA.
B5: Vendedor:
B6: Fecha: | D6: =TODAY() -> 46181
B7: Datos del cliente
B8: Nombre:
B9: CI o RUC:
B10: Dirección:
B11: Ciudad de entrega:
B12: Número de teléfono: | E12: CBM: | F12: ='1.CÁL'!Q6/1.1 -> 0
B13: Email: | E13: Cantidad de caja: | F13: ='1.CÁL'!K6 -> 3
B14: No. Doc Cotización: | E14: Peso: | F14: ='1.CÁL'!R6 -> 0
B15: Item | D15: Detalle | E15: Total
B16: 1 | D16: Valor de la Mercadería | E16: ='1.CÁL'!C14+'1.CÁL'!T6 -> 0
B17: 2 | D17: Gastos Internos en China | E17: ='1.CÁL'!D14+'1.CÁL'!J14 -> 0
B18: 3 | D18: Flete Marítimo | E18: ='1.CÁL'!E14 -> 0
B19: 4 | D19: Seguro | E19: ='1.CÁL'!F14 -> #DIV/0!
B20: 5 | D20: Comisión Bancaria | E20: ='1.CÁL'!I14 -> #DIV/0!
B21: 6 | D21: Transporte Ecuador (dirección acordada) | E21: ='1.CÁL'!K14 -> 10
B22: 7 | D22: Arancel + 0.5% FODINFA | E22: ='1.CÁL'!M14+'1.CÁL'!L14 -> #DIV/0!
B23: 8 | D23: Impuesto Específico | E23: ='1.CÁL'!O14+'1.CÁL'!N14 -> #DIV/0!
B24: 9 | D24: Servicios Logísticos | E24: ='1.CÁL'!Q14 -> 180
B25: 10 | D25: Gastos de Aduana | E25: ='1.CÁL'!R14 -> 1
B26: 11 | D26: Custodia Armada y Candado | E26: ='1.CÁL'!S14 -> 0
B27: 12 | D27: Tax (Opcional) | E27: ='1.CÁL'!V14 -> 0
B28: 13 | D28: Certificado de origen | E28: ='1.CÁL'!U14 -> 0
B29: 14 | D29: ICE | E29: 0
B30: 15 | D30: PRECIO FINAL EN ECUADOR | E30: =SUM(E16:F29)+F39 -> #DIV/0!
B31: 16 | D31: IVA | E31: ='1.CÁL'!P14 -> #DIV/0!
B32: 17 | D32: Salida Divisas ISD | E32: ='1.CÁL'!G14 -> #DIV/0!
D33: TOTAL | E33: =SUM(E30:F32) -> #DIV/0!
B34: *En pago al contado (transferencia, depósito, efectivo), se otorga un descuento al cliente* | E34: Valor | F34: Pago al contado incluido descuento
E35: =F35*1.055 -> #DIV/0! | F35: =E33 -> #DIV/0! | G35: =IF(F35=F65,"","no coinciden") -> #DIV/0!
B36: Pago 1 | E36: =F36*1.055 -> #DIV/0! | F36: =SUM(E16:F20)+E32+(E24*50%) -> #DIV/0!
B37: Pago 2 | E37: =F37*1.055 -> #DIV/0! | F37: =+E21+E22+E23+E25+E26+E31+F39+E27+E29+E28+(E24*50%) -> #DIV/0!
B38: Observaciones :
B39: Seguro de transporte interno | E39: 0.006 | F39: ='1.CÁL'!T14 -> #DIV/0!
B40: *La liquidación presentada al cliente se basa en la información proporcionada por el proveedor; la cual podría ser actualizada en caso de existir alguna variación en precios de los productos, flete o CBM*
B41: *La tarifa de flete marítimo esta cotizada a la semana actual, podrá varíar si existe cambios en las tarifas generales de flete marítimo.
B42: *En caso de recibir mercadería adicional (muestras, regalos, etc.) enviada por el proveedor se deberá actualizar la liquidación*
...

Sheet b. LIQ.F
B2: =IF(OR('1.CÁL'!$D$30=TRUE,'1.CÁL'!$F$30="OK"),"LIQUIDACIÓN CORRECTA","NO VÁLIDA") -> #DIV/0! | J2: =IF(OR('1.CÁL'!$D$31=TRUE,'1.CÁL'!$F$31="OK"),"LIQUIDACIÓN CORRECTA","NO VÁLIDA") -> #DIV/0! | R2: =IF(OR('1.CÁL'!$D$32=TRUE,'1.CÁL'!$F$32="OK"),"LIQUIDACIÓN CORRECTA","NO VÁLIDA") -> #DIV/0!
B9: NEGOCIOS CESCH CIA.LTDA. | J9: NEGOCIOS CESCH CIA.LTDA. | R9: NEGOCIOS CESCH CIA.LTDA.
B12: Vendedor: | J12: Vendedor: | R12: Vendedor:
B13: Fecha: | D13: =TODAY() -> 46181 | J13: Fecha: | L13: =TODAY() -> 46181 | R13: Fecha: | T13: =TODAY() -> 46181
B14: Datos del cliente | J14: Datos del cliente | R14: Datos del cliente
B15: Nombre: | J15: Nombre: | R15: Nombre:
B16: CI o RUC: | J16: CI o RUC: | R16: CI o RUC:
B17: Dirección: | J17: Dirección: | R17: Dirección:
B18: Ciudad de entrega: | J18: Ciudad de entrega: | R18: Ciudad de entrega:
B19: Número de teléfono: | E19: CBM: | F19: ='1.CÁL'!Q6/1.1 -> 0 | J19: Número de teléfono: | M19: CBM: | N19: ='1.CÁL'!Q6/1.1 -> 0 | R19: Número de teléfono: | U19: CBM: | V19: ='1.CÁL'!Q6/1.1 -> 0
B20: Email: | E20: Cantidad de caja: | F20: ='1.CÁL'!K6 -> 3 | J20: Email: | M20: Cantidad de caja: | N20: ='1.CÁL'!K6 -> 3 | R20: Email: | U20: Cantidad de caja: | V20: ='1.CÁL'!K6 -> 3
B21: No. Doc Cotización: | E21: Peso: | J21: No. Doc Cotización: | M21: Peso: | N21: ='1.CÁL'!AF6 | R21: No. Doc Cotización: | U21: Peso: | V21: ='1.CÁL'!AJ6
B22: Item | D22: Detalle | E22: Total | J22: Item | L22: Detalle | M22: Total | R22: Item | T22: Detalle | U22: Total
B23: 1 | D23: Compra | E23: ='2.FAC'!C16+'2.FAC'!H16 -> 0 | J23: 1 | L23: Compra | M23: ='2.FAC'!C21+'2.FAC'!H21 -> 0 | R23: 1 | T23: Compra | U23: ='2.FAC'!C26+'2.FAC'!H26 -> 0
B24: 2 | D24: Gasto Origen | E24: ='2.FAC'!D16+'2.FAC'!E16+'2.FAC'!F16+'2.FAC'!G16+'2.FAC'!I16+'2.FAC'!J16 -> 0 | J24: 2 | L24: Gasto Origen | M24: ='2.FAC'!D21+'2.FAC'!E21+'2.FAC'!F21+'2.FAC'!G21+'2.FAC'!I21+'2.FAC'!J21 -> 0 | R24: 2 | T24: Gasto Origen | U24: ='2.FAC'!D26+'2.FAC'!E26+'2.FAC'!F26+'2.FAC'!G26+'2.FAC'!I26+'2.FAC'!J26 -> 0
B25: 3 | D25: Gasto Nacionalización | E25: ='2.FAC'!L16+'2.FAC'!P16+'2.FAC'!M16+'2.FAC'!Q16+'2.FAC'!R16+'2.FAC'!K16+'2.FAC'!S16+F32 -> #DIV/0! | J25: 3 | L25: Gasto Nacionalización | M25: ='2.FAC'!L21+'2.FAC'!P21+'2.FAC'!M21+'2.FAC'!Q21+'2.FAC'!R21+'2.FAC'!K21+'2.FAC'!S21+N32 -> #DIV/0! | R25: 3 | T25: Gasto Nacionalización | U25: ='2.FAC'!L26+'2.FAC'!P26+'2.FAC'!M26+'2.FAC'!Q26+'2.FAC'!R26+'2.FAC'!K26+'2.FAC'!S26+V32 -> #DIV/0!
E26: Valor | F26: Descuento pago al contado | M26: Valor | N26: Descuento pago al contado | U26: Valor | V26: Descuento pago al contado
B27: TOTAL | E27: =F27*1.055 -> #DIV/0! | F27: =SUM(E23:F25) -> #DIV/0! | J27: TOTAL | M27: =N27*1.055 -> #DIV/0! | N27: =SUM(M23:N25) -> #DIV/0! | R27: TOTAL | U27: =V27*1.055 -> #DIV/0! | V27: =SUM(U23:V25) -> #DIV/0!
B29: Pago 1 | E29: =F29*1.055 -> 0 | F29: =E23+E24 -> 0 | J29: Pago 1 | M29: =N29*1.055 -> 0 | N29: =M23+M24 -> 0 | R29: Pago 1 | U29: =V29*1.055 -> 0 | V29: =U23+U24 -> 0
B30: Pago 2 | E30: =F30*1.055 -> #DIV/0! | F30: =E25 -> #DIV/0! | J30: Pago 2 | M30: =N30*1.055 -> #DIV/0! | N30: =M25 -> #DIV/0! | R30: Pago 2 | U30: =V30*1.055 -> #DIV/0! | V30: =U25 -> #DIV/0!
B31: Observaciones : | J31: Observaciones : | R31: Observaciones :
C32: Seguro de transporte interno (opcional) | E32: 0.006 | F32: ='2.FAC'!T16 -> #DIV/0! | K32: Seguro de transporte interno (opcional) | M32: 0.006 | N32: ='2.FAC'!T21 -> #DIV/0! | S32: Seguro de transporte interno (opcional) | U32: 0.006 | V32: ='2.FAC'!T26 -> #DIV/0!
B33: *La liquidación presentada al cliente se basa en la información proporcionada por el proveedor; la cual podría ser actualizada en caso de existir alguna variación en precios de los productos, flete o CBM* | J33: *La liquidación presentada al cliente se basa en la información proporcionada por el proveedor; la cual podría ser actualizada en caso de existir alguna variación en precios de los productos, flete o CBM* | R33: *La liquidación presentada al cliente se basa en la información proporcionada por el proveedor; la cual podría ser actualizada en caso de existir alguna variación en precios de los productos, flete o CBM*
B34: *En caso de recibir mercadería adicional (muestras, regalos, etc.) enviada por el proveedor se deberá actualizar la liquidación* | J34: *En caso de recibir mercadería adicional (muestras, regalos, etc.) enviada por el proveedor se deberá actualizar la liquidación* | R34: *En caso de recibir mercadería adicional (muestras, regalos, etc.) enviada por el proveedor se deberá actualizar la liquidación*
B35: *La liquidación tiene vigencia de 7 días* | J35: *La liquidación tiene vigencia de 7 días* | R35: *La liquidación tiene vigencia de 7 días*
B36: *La liquidación tendrá validez una vez firmado el contrato de representación internacional e intermediación* | J36: *La liquidación tendrá validez una vez firmado el contrato de representación internacional e intermediación* | R36: *La liquidación tendrá validez una vez firmado el contrato de representación internacional e intermediación*
B37: *El precio de la liquidación incluye IVA* | J37: *El precio de la liquidación incluye IVA* | R37: *El precio de la liquidación incluye IVA*
B38: *EL IVA se calcula por el 13% ya que se considera que la mercadería llegará después del cambio del impuesto a Ecuador | J38: *EL IVA se calcula por el 13% ya que se considera que la mercadería llegará después del cambio del impuesto a Ecuador | R38: *EL IVA se calcula por el 13% ya que se considera que la mercadería llegará después del cambio del impuesto a Ecuador
B39: *Es importante negociar con el proveedor el empacado del producto para su preservación durante el transporte* | J39: *Es importante negociar con el proveedor el empacado del producto para su preservación durante el transporte* | R39: *Es importante negociar con el proveedor el empacado del producto para su preservación durante el transporte*
B40: Rubros no incluidos | J40: Rubros no incluidos | R40: Rubros no incluidos
B41: **El costo del transporte nacional (Ecuador-envío a la dirección deseada) es necesario coordinar con el asesor** | J41: **El costo del transporte nacional (Ecuador-envío a la dirección deseada) es necesario coordinar con el asesor** | R41: **El costo del transporte nacional (Ecuador-envío a la dirección deseada) es necesario coordinar con el asesor**
B42: **En caso de ser necesario se adicionará el rubro para la contratación de montacargas en China para el adecuado manejo de carga** | J42: **En caso de ser necesario se adicionará el rubro para la contratación de montacargas en China para el adecuado manejo de carga** | R42: **En caso de ser necesario se adicionará el rubro para la contratación de montacargas en China para el adecuado manejo de carga**
B43: **No se cubre el rubro de descargue de la mercadería en la dirección (montacargas, personal, etc), eso debe ser gestionado por el cliente** | J43: **No se cubre el rubro de descargue de la mercadería en la dirección (montacargas, personal, etc), eso debe ser gestionado por el cliente** | R43: **No se cubre el rubro de descargue de la mercadería en la dirección (montacargas, personal, etc), eso debe ser gestionado por el cliente**
B49: =B2 -> #DIV/0! | J49: =J2 -> #DIV/0! | R49: =R2 -> #DIV/0!
B51: NEGOCIOS CESCH CIA.LTDA. | J51: NEGOCIOS CESCH CIA.LTDA. | R51: NEGOCIOS CESCH CIA.LTDA.
B54: Asesor: | J54: Asesor: | R54: Asesor:
B55: Fecha: | D55: =TODAY() -> 46181 | J55: Fecha: | L55: =TODAY() -> 46181 | R55: Fecha: | T55: =TODAY() -> 46181
B56: Datos del cliente | J56: Datos del cliente | R56: Datos del cliente
B57: Nombre: | J57: Nombre: | R57: Nombre:
B58: CI o RUC: | J58: CI o RUC: | R58: CI o RUC:
...

Sheet c. LIQ LCL D
B2: =IF(OR('1.CÁL'!$D$29=TRUE,'1.CÁL'!$F$29="OK"),"LIQUIDACIÓN CORRECTA","NO VÁLIDA") -> #DIV/0!
B3: NEGOCIOS CESCH CIA.LTDA.
B5: Vendedor:
B6: Fecha: | D6: =TODAY() -> 46181
B7: Fecha Validez: | D7: =TODAY()+7 -> 46188
B8: Datos del cliente
B9: Nombre:
B10: CI o RUC:
B11: Dirección:
B12: Ciudad de entrega: | E12: Termino: | F12: FOB
B13: Número de teléfono: | E13: CBM: | F13: ='1.CÁL'!Q6/1.1 -> 0
B14: Email: | E14: Cantidad de caja: | F14: ='1.CÁL'!K6 -> 3
B15: No. Doc Cotización: | E15: Peso: | F15: ='1.CÁL'!R6 -> 0
B17: Item | D17: Detalle | E17: Total | F17: IVA
B18: 1 | D18: MERCADERIA | E18: =SUM(E19) -> 0 | F18: =SUM(F19) -> 0
B19: 1.1 | D19: ='3. LCL D'!B1 -> VALOR USD | E19: ='3. LCL D'!B7 -> 0 | F19: ='3. LCL D'!B6 -> 0
B21: 2 | D21: SERVICIOS DE NEGOCIOS CESCH | E21: =SUM(E22:E28) -> 911 | F21: =SUM(F22:F28) -> 130.5
B22: 2.1 | D22: ='3. LCL D'!H1 -> VERIFICACION DEL PROVEEDOR NO | E22: ='3. LCL D'!H5 -> 0 | F22: ='3. LCL D'!H6 -> 0
B23: 2.2 | D23: ='3. LCL D'!C1 -> COSTO DE EXPORTACION (EXW A FOB) | E23: ='3. LCL D'!C7 -> 0 | F23: ='3. LCL D'!C6 -> 0
B24: 2.3 | D24: ='3. LCL D'!D1&" $"&E24/F13&" W/M" -> #DIV/0! | E24: ='3. LCL D'!D7 -> 41 | F24: ='3. LCL D'!D6 -> 0
B25: 2.4 | D25: ='3. LCL D'!E1 -> SEGURO | E25: ='3. LCL D'!E5 -> 30 | F25: ='3. LCL D'!E6 -> 4.5
B26: 2.5 | D26: ='3. LCL D'!O1 -> SERVICIOS LOGISTICOS | E26: ='3. LCL D'!O5 -> 180 | F26: ='3. LCL D'!O6 -> 27
B27: 2.6 | D27: ='3. LCL D'!P1 -> GASTOS LOCALES | E27: ='3. LCL D'!P5 -> 380 | F27: ='3. LCL D'!P6 -> 57
B28: 2.7 | D28: ='3. LCL D'!Q1 -> AGENTE DE ADUANA | E28: ='3. LCL D'!Q5 -> 280 | F28: ='3. LCL D'!Q6 -> 42
B30: 3 | D30: IMPUESTOS | E30: =SUM(E31:E35) -> #DIV/0! | F30: =SUM(F31:F35) -> #DIV/0!
B31: 3.1 | D31: ='3. LCL D'!J1 -> AD-VALOREM | E31: ='3. LCL D'!J5 -> #DIV/0! | F31: ='3. LCL D'!J6 -> #DIV/0!
B32: 3.2 | D32: ='3. LCL D'!K1 -> FODINFA | E32: ='3. LCL D'!K5 -> #DIV/0! | F32: ='3. LCL D'!K6 -> #DIV/0!
B33: 3.3 | D33: ='3. LCL D'!L1 -> ICE | E33: ='3. LCL D'!L5 -> #DIV/0! | F33: ='3. LCL D'!L6 -> #DIV/0!
B34: 3.4 | D34: ='3. LCL D'!M1 -> IMPUESTOS ESPECIFICOS | E34: ='3. LCL D'!M5 -> 0 | F34: ='3. LCL D'!M6 -> 0
B35: 3.5 | D35: ='3. LCL D'!N1 -> IVA SENAE | E35: ='3. LCL D'!N5 -> #DIV/0! | F35: ='3. LCL D'!N6 -> #DIV/0!
B37: 4 | D37: OTRO COSTOS A TOMAR EN CUENTA | E37: =SUM(E38:E42) -> 195.62 | F37: =SUM(F38:F42) -> 27.5355
B38: 4.1 | D38: ='3. LCL D'!F1 -> SALIDA DIVISAS ISD | E38: ='3. LCL D'!F5 -> 2.05 | F38: ='3. LCL D'!F6 -> 0
B39: 4.2 | D39: ='3. LCL D'!G1 -> COMISIÓN BANCARIA (2 X PROVEEDOR) | E39: ='3. LCL D'!G5 -> 140 | F39: ='3. LCL D'!G6 -> 21
B40: 4.3 | D40: ='3. LCL D'!R1 -> DEPOSITO TEMPORAL | E40: ='3. LCL D'!R5 -> 43.57 | F40: ='3. LCL D'!R6 -> 6.5355
B41: 4.4 | D41: ='3. LCL D'!S1 -> TRANSPORTE INTERNO ECUADOR | E41: ='3. LCL D'!S5 -> 10 | F41: ='3. LCL D'!S6 -> 0
B42: 4.5 | D42: ='3. LCL D'!T1 -> CANDADO | E42: ='3. LCL D'!T5 -> 0 | F42: ='3. LCL D'!T6 -> 0
D44: Subtotal | E44: =E18+E21+E30+E37 -> #DIV/0!
D45: Total con IVA | E45: =E44+F21+F30+F37 -> #DIV/0!
B47: DETALLE DE PAGOS PARA SERVICIOS EFECTUADOS POR NEGOCIOS CESCH INCLUIDO IVA | E47: Valor | F47: Pago al contado incluido descuento
B48: Pago 1 | E48: =SUM(E22:F22,E23:F23,E25:F25,E26:F26)*1.055 -> 254.7825 | F48: =SUM(E22:F22,E23:F23,E25:F25,E26:F26) -> 241.5
...

Sheet DETALLE IMPORTACION
B1: VERSION 1.1
B2: DETALLE DE IMPORTACIÓN
B3: Asesor | F3: Datos cliente | G3: =IF(C4=TRUE,"ESCRIBIR DATOS COMPLETOS",0) -> 0
B4: Cliente nuevo | C4: FALSE | F4: Nombres: | G4: =IF(C5=TRUE,"CLIENTE EXISTENTE, PONER SOLO NOMBRE DE LA CUENTA",0) -> 0
B5: Cliente existente | C5: FALSE | F5: RUC o CI:
B6: Link de la carpeta | F6: Correo:
B7: Número de proveedores | C7: ='1.CÁL'!D16 -> 2 | F7: Telefono:
F8: Dirección facturación:
F9: Direccion de entrega: | G9: Especificar dirección de entrega
B11: PA | D11: =IFERROR(IF((COUNTIFS('1.CÁL'!$C$3:$C$5,"PA") - COUNTIFS('1.CÁL'!$C$3:$C$5,"PA",'1.CÁL'!$AD$3:$AD$5,"NO"))>0,"REQUIERE PERMISO","SIN PERMISO"),"REVISAR") -> SIN PERMISO
B12: # de artículos | C12: =COUNTIF('1.CÁL'!C3:C5,"PA") -> 2
B13: Divisa | C13: RMB | D13: USD | E13: YUAN
B14: Valor EXW | C14: =SUMIF('1.CÁL'!C3:C5,"PA",'1.CÁL'!O3:O5) -> 0 | D14: =SUMIF(C13,"USD",C16) -> 0 | E14: =SUMIF(C13,"RMB",C16)*6.8 -> 0
B15: Valor de envio a Yiwu | C15: =SUMIF('1.CÁL'!C3:C5,"PA",'1.CÁL'!T3:T5) -> 0
B16: Total factura usd | C16: =C14+C15 -> 0
B17: Comision bancaria | C17: =SUMIF('1.CÁL'!C3:C5,"PA",'1.CÁL'!I11:I13) -> #DIV/0!
B18: Enlace proforma
B19: Télefono del proveedor | C19: =IF(C20="Existente","Existente","falta contacto proveedor") -> falta contacto proveedor
B20: Tipo de proveedor | C20: Nuevo
B21: Tipo de pago
B22: Cotizador
B23: Observaciones OP:
B24: Nota para Nico:
B26: PB | D26: =IFERROR(IF((COUNTIFS('1.CÁL'!$C$3:$C$5,"PB") - COUNTIFS('1.CÁL'!$C$3:$C$5,"PB",'1.CÁL'!$AD$3:$AD$5,"NO"))>0,"REQUIERE PERMISO","SIN PERMISO"),"REVISAR") -> SIN PERMISO
B27: # de artículos | C27: =COUNTIF('1.CÁL'!C3:C5,"PB") -> 1
B28: Divisa | C28: USD | D28: USD | E28: YUAN
B29: Valor EXW | C29: =SUMIF('1.CÁL'!C3:C5,"PB",'1.CÁL'!O3:O5) -> 0 | D29: =SUMIF(C28,"USD",C31) -> 0 | E29: =SUMIF(C28,"RMB",C31)*6.8 -> 0
B30: Valor de envio a Yiwu | C30: =SUMIF('1.CÁL'!C3:C5,"PB",'1.CÁL'!T3:T5) -> 0
B31: Total factura usd | C31: =C29+C30 -> 0
B32: Comision bancaria | C32: =SUMIF('1.CÁL'!C3:C5,"PB",'1.CÁL'!I11:I13) -> #DIV/0!
B33: Enlace proforma
B34: Télefono del proveedor | C34: =IF(C35="Existente","Existente","falta contacto proveedor") -> falta contacto proveedor
B35: Tipo de proveedor | C35: Nuevo
B36: Tipo de pago
B37: Cotizador
B38: Observaciones OP:
B39: Nota para Nico:
B41: PC | D41: =IFERROR(IF((COUNTIFS('1.CÁL'!$C$3:$C$5,"PC") - COUNTIFS('1.CÁL'!$C$3:$C$5,"PC",'1.CÁL'!$AD$3:$AD$5,"NO"))>0,"REQUIERE PERMISO","SIN PERMISO"),"REVISAR") -> SIN PERMISO
B42: # de artículos | C42: =COUNTIF('1.CÁL'!C3:C5,"PC") -> 0
B43: Divisa | C43: RMB | D43: USD | E43: YUAN
...

Sheet 4.1 ARTICULOS
A1: Oportunidad__r.Nombre | B1: Modelo | C1: Articulo | D1: Descripción del Producto | E1: Categorías | F1: Url del Artículo | G1: Link del Articulo | H1: Contacto_Proveedor__r.Nombre completo | I1: Orden_Proveedor__r.Orden Proveedor NÂº | J1: Partida_Arancelaria__r.PARTIDA | K1: Aranceles | L1: Cantidad | M1: Unidad | N1: Precio de venta unitario | O1: CBM Vendido | P1: Peso Vendido (Kg) | Q1: Moneda de Pago | R1: Precio de compra unitario (EXW)
B2: ='1.CÁL'!D3 | C2: =CONCATENATE(ROW()-1,") ",LEFT('1.CÁL'!H3,70)) -> 1) | D2: =IF('1.CÁL'!G3="",C2,CONCATENATE(ROW()-1,") ",LEFT('1.CÁL'!G3,140))) -> 1) | E2: Maquinaria y Repuestos | F2: ='1.CÁL'!F3 -> https://drive.google.com/uc?export=view&id=1vcrZn_OLPxflHITc9KAVYfonNcP_7xys | G2: =MID('1.CÁL'!A3,1,250) | H2: Bruna Zubiaga | I2: OP-0000005 | J2: =TRIM(CONCATENATE(TRIM('1.CÁL'!AB3),"_",'1.CÁL'!AC3)) -> _ | L2: ='1.CÁL'!L3 -> 1 | M2: ='1.CÁL'!I3 -> PZA | N2: =IF('1.CÁL'!$W$14<3000,'1.CÁL'!Z11,'1.CÁL'!X11) -> #DIV/0! | O2: ='1.CÁL'!S3 -> 0 | P2: ='1.CÁL'!R3 | Q2: =IF('1.CÁL'!M3>0,"Yuán","Dólar") -> Dólar | R2: =IF(Q2="Dólar",'1.CÁL'!N3,'1.CÁL'!M3)
I3: =I2 -> OP-0000005 | M3: ='1.CÁL'!I4 -> PZA
I4: OP-0000005 | M4: ='1.CÁL'!I5 -> PZA
I5: OP-0000005
I6: OP-0000005
I7: OP-0000005
I8: OP-0000005
I9: OP-0000005
I10: OP-0000005
I11: OP-0000005
I12: OP-0000005
I13: OP-0000005
I14: OP-0000005
I15: OP-0000005
I16: OP-0000005
... I300: OP-0000005
